Traceback (most recent call last):
  File "C:\Users\TWP\Documents\GitHub\beudei\whatsapp_gonder.py", line 34, in whatsapp_mesaj_gonder
    mesaj_kutusu = wait.until(
        EC.presence_of_element_located((By.XPATH, "//div[@contenteditable='true'][@data-tab='10']"))
    )
  File "C:\Users\TWP\AppData\Local\Programs\Python\Python313\Lib\site-packages\selenium\webdriver\support\wait.py", line 137, in until
    value = method(self._driver)
  File "C:\Users\TWP\AppData\Local\Programs\Python\Python313\Lib\site-packages\selenium\webdriver\support\expected_conditions.py", line 110, in _predicate
    return driver.find_element(*locator)
           ~~~~~~~~~~~~~~~~~~~^^^^^^^^^^
  File "C:\Users\TWP\AppData\Local\Programs\Python\Python313\Lib\site-packages\selenium\webdriver\remote\webdriver.py", line 917, in find_element
    return self.execute(Command.FIND_ELEMENT, {"using": by, "value": value})["value"]
           ~~~~~~~~~~~~^^^^^^^^^^^^^^^^^^^^^^^^^^^^^^^^^^^^^^^^^^^^^^^^^^^^^
  File "C:\Users\TWP\AppData\Local\Programs\Python\Python313\Lib\site-packages\selenium\webdriver\remote\webdriver.py", line 448, in execute
    self.error_handler.check_response(response)
    ~~~~~~~~~~~~~~~~~~~~~~~~~~~~~~~~~^^^^^^^^^^
  File "C:\Users\TWP\AppData\Local\Programs\Python\Python313\Lib\site-packages\selenium\webdriver\remote\errorhandler.py", line 232, in check_response
    raise exception_class(message, screen, stacktrace)
selenium.common.exceptions.WebDriverException: Message: target frame detached
  (failed to check if window was closed: disconnected: not connected to DevTools)
  (Session info: chrome=138.0.7204.51)
Stacktrace:
	GetHandleVerifier [0x0x491a33+62339]
	GetHandleVerifier [0x0x491a74+62404]
	(No symbol) [0x0x2d1f80]
	(No symbol) [0x0x2c2b70]
	(No symbol) [0x0x2c1ce1]
	(No symbol) [0x0x2df8f2]
	(No symbol) [0x0x345cbc]
	(No symbol) [0x0x360089]
	(No symbol) [0x0x33f1b6]
	(No symbol) [0x0x30e7a2]
	(No symbol) [0x0x30f644]
	GetHandleVerifier [0x0x7065c3+2637587]
	GetHandleVerifier [0x0x7019ca+2618138]
	GetHandleVerifier [0x0x4b84aa+220666]
	GetHandleVerifier [0x0x4a88d8+156200]
	GetHandleVerifier [0x0x4af06d+182717]
	GetHandleVerifier [0x0x499978+94920]
	GetHandleVerifier [0x0x499b02+95314]
	GetHandleVerifier [0x0x484c4a+9626]
	BaseThreadInitThunk [0x0x757b5d49+25]
	RtlInitializeExceptionChain [0x0x76efd1ab+107]
	RtlGetAppContainerNamedObjectPath [0x0x76efd131+561]


During handling of the above exception, another exception occurred:

Traceback (most recent call last):
  File "C:\Users\TWP\Documents\GitHub\beudei\whatsapp_gonder.py", line 45, in whatsapp_mesaj_gonder
    driver.save_screenshot("whatsapp_error.png")
    ~~~~~~~~~~~~~~~~~~~~~~^^^^^^^^^^^^^^^^^^^^^^
  File "C:\Users\TWP\AppData\Local\Programs\Python\Python313\Lib\site-packages\selenium\webdriver\remote\webdriver.py", line 1013, in save_screenshot
    return self.get_screenshot_as_file(filename)
           ~~~~~~~~~~~~~~~~~~~~~~~~~~~^^^^^^^^^^
  File "C:\Users\TWP\AppData\Local\Programs\Python\Python313\Lib\site-packages\selenium\webdriver\remote\webdriver.py", line 988, in get_screenshot_as_file
    png = self.get_screenshot_as_png()
  File "C:\Users\TWP\AppData\Local\Programs\Python\Python313\Lib\site-packages\selenium\webdriver\remote\webdriver.py", line 1022, in get_screenshot_as_png
    return b64decode(self.get_screenshot_as_base64().encode("ascii"))
                     ~~~~~~~~~~~~~~~~~~~~~~~~~~~~~^^
  File "C:\Users\TWP\AppData\Local\Programs\Python\Python313\Lib\site-packages\selenium\webdriver\remote\webdriver.py", line 1032, in get_screenshot_as_base64
    return self.execute(Command.SCREENSHOT)["value"]
           ~~~~~~~~~~~~^^^^^^^^^^^^^^^^^^^^
  File "C:\Users\TWP\AppData\Local\Programs\Python\Python313\Lib\site-packages\selenium\webdriver\remote\webdriver.py", line 448, in execute
    self.error_handler.check_response(response)
    ~~~~~~~~~~~~~~~~~~~~~~~~~~~~~~~~~^^^^^^^^^^
  File "C:\Users\TWP\AppData\Local\Programs\Python\Python313\Lib\site-packages\selenium\webdriver\remote\errorhandler.py", line 232, in check_response
    raise exception_class(message, screen, stacktrace)
selenium.common.exceptions.InvalidSessionIdException: Message: invalid session id: session deleted as the browser has closed the connection
from disconnected: not connected to DevTools
  (Session info: chrome=138.0.7204.51)
Stacktrace:
	GetHandleVerifier [0x0x491a33+62339]
	GetHandleVerifier [0x0x491a74+62404]
	(No symbol) [0x0x2d2123]
	(No symbol) [0x0x2c1b30]
	(No symbol) [0x0x2df8f2]
	(No symbol) [0x0x345cbc]
	(No symbol) [0x0x360089]
	(No symbol) [0x0x33f1b6]
	(No symbol) [0x0x30e7a2]
	(No symbol) [0x0x30f644]
	GetHandleVerifier [0x0x7065c3+2637587]
	GetHandleVerifier [0x0x7019ca+2618138]
	GetHandleVerifier [0x0x4b84aa+220666]
	GetHandleVerifier [0x0x4a88d8+156200]
	GetHandleVerifier [0x0x4af06d+182717]
	GetHandleVerifier [0x0x499978+94920]
	GetHandleVerifier [0x0x499b02+95314]
	GetHandleVerifier [0x0x484c4a+9626]
	BaseThreadInitThunk [0x0x757b5d49+25]
	RtlInitializeExceptionChain [0x0x76efd1ab+107]
	RtlGetAppContainerNamedObjectPath [0x0x76efd131+561]

Traceback (most recent call last):
  File "C:\Users\Trenkwalder\Documents\GitHub\beudei\whatsapp_gonder.py", line 27, in whatsapp_mesaj_gonder
    driver.set_window_size(800, 600)  # Biraz daha büyük pencere
    ^^^^^^^^^^^^^^^^^^^^^^^^^^^^^^^^
  File "C:\Users\Trenkwalder\AppData\Local\Packages\PythonSoftwareFoundation.Python.3.11_qbz5n2kfra8p0\LocalCache\local-packages\Python311\site-packages\selenium\webdriver\remote\webdriver.py", line 1050, in set_window_size
    self.set_window_rect(width=int(width), height=int(height))
  File "C:\Users\Trenkwalder\AppData\Local\Packages\PythonSoftwareFoundation.Python.3.11_qbz5n2kfra8p0\LocalCache\local-packages\Python311\site-packages\selenium\webdriver\remote\webdriver.py", line 1130, in set_window_rect
    return self.execute(Command.SET_WINDOW_RECT, {"x": x, "y": y, "width": width, "height": height})["value"]
           ^^^^^^^^^^^^^^^^^^^^^^^^^^^^^^^^^^^^^^^^^^^^^^^^^^^^^^^^^^^^^^^^^^^^^^^^^^^^^^^^^^^^^^^^^
  File "C:\Users\Trenkwalder\AppData\Local\Packages\PythonSoftwareFoundation.Python.3.11_qbz5n2kfra8p0\LocalCache\local-packages\Python311\site-packages\selenium\webdriver\remote\webdriver.py", line 448, in execute
    self.error_handler.check_response(response)
  File "C:\Users\Trenkwalder\AppData\Local\Packages\PythonSoftwareFoundation.Python.3.11_qbz5n2kfra8p0\LocalCache\local-packages\Python311\site-packages\selenium\webdriver\remote\errorhandler.py", line 232, in check_response
    raise exception_class(message, screen, stacktrace)
selenium.common.exceptions.NoSuchWindowException: Message: no such window: target window already closed
from unknown error: web view not found
  (Session info: chrome=138.0.7204.158)
Stacktrace:
	GetHandleVerifier [0x0x9f1a33+62339]
	GetHandleVerifier [0x0x9f1a74+62404]
	(No symbol) [0x0x832123]
	(No symbol) [0x0x810fc9]
	(No symbol) [0x0x8a5aee]
	(No symbol) [0x0x8c0089]
	(No symbol) [0x0x89f1b6]
	(No symbol) [0x0x86e7a2]
	(No symbol) [0x0x86f644]
	GetHandleVerifier [0x0xc665c3+2637587]
	GetHandleVerifier [0x0xc619ca+2618138]
	GetHandleVerifier [0x0xa184aa+220666]
	GetHandleVerifier [0x0xa088d8+156200]
	GetHandleVerifier [0x0xa0f06d+182717]
	GetHandleVerifier [0x0x9f9978+94920]
	GetHandleVerifier [0x0x9f9b02+95314]
	GetHandleVerifier [0x0x9e4c4a+9626]
	BaseThreadInitThunk [0x0x75f45d49+25]
	RtlInitializeExceptionChain [0x0x7729d1ab+107]
	RtlGetAppContainerNamedObjectPath [0x0x7729d131+561]

Traceback (most recent call last):
  File "C:\Users\Trenkwalder\Documents\GitHub\beudei\whatsapp_gonder.py", line 27, in whatsapp_mesaj_gonder
    driver.set_window_size(800, 600)  # Biraz daha büyük pencere
    ^^^^^^^^^^^^^^^^^^^^^^^^^^^^^^^^
  File "C:\Users\Trenkwalder\AppData\Local\Packages\PythonSoftwareFoundation.Python.3.11_qbz5n2kfra8p0\LocalCache\local-packages\Python311\site-packages\selenium\webdriver\remote\webdriver.py", line 1050, in set_window_size
    self.set_window_rect(width=int(width), height=int(height))
  File "C:\Users\Trenkwalder\AppData\Local\Packages\PythonSoftwareFoundation.Python.3.11_qbz5n2kfra8p0\LocalCache\local-packages\Python311\site-packages\selenium\webdriver\remote\webdriver.py", line 1130, in set_window_rect
    return self.execute(Command.SET_WINDOW_RECT, {"x": x, "y": y, "width": width, "height": height})["value"]
           ^^^^^^^^^^^^^^^^^^^^^^^^^^^^^^^^^^^^^^^^^^^^^^^^^^^^^^^^^^^^^^^^^^^^^^^^^^^^^^^^^^^^^^^^^
  File "C:\Users\Trenkwalder\AppData\Local\Packages\PythonSoftwareFoundation.Python.3.11_qbz5n2kfra8p0\LocalCache\local-packages\Python311\site-packages\selenium\webdriver\remote\webdriver.py", line 448, in execute
    self.error_handler.check_response(response)
  File "C:\Users\Trenkwalder\AppData\Local\Packages\PythonSoftwareFoundation.Python.3.11_qbz5n2kfra8p0\LocalCache\local-packages\Python311\site-packages\selenium\webdriver\remote\errorhandler.py", line 232, in check_response
    raise exception_class(message, screen, stacktrace)
selenium.common.exceptions.NoSuchWindowException: Message: no such window: target window already closed
from unknown error: web view not found
  (Session info: chrome=138.0.7204.158)
Stacktrace:
	GetHandleVerifier [0x0x9f1a33+62339]
	GetHandleVerifier [0x0x9f1a74+62404]
	(No symbol) [0x0x832123]
	(No symbol) [0x0x810fc9]
	(No symbol) [0x0x8a5aee]
	(No symbol) [0x0x8c0089]
	(No symbol) [0x0x89f1b6]
	(No symbol) [0x0x86e7a2]
	(No symbol) [0x0x86f644]
	GetHandleVerifier [0x0xc665c3+2637587]
	GetHandleVerifier [0x0xc619ca+2618138]
	GetHandleVerifier [0x0xa184aa+220666]
	GetHandleVerifier [0x0xa088d8+156200]
	GetHandleVerifier [0x0xa0f06d+182717]
	GetHandleVerifier [0x0x9f9978+94920]
	GetHandleVerifier [0x0x9f9b02+95314]
	GetHandleVerifier [0x0x9e4c4a+9626]
	BaseThreadInitThunk [0x0x75f45d49+25]
	RtlInitializeExceptionChain [0x0x7729d1ab+107]
	RtlGetAppContainerNamedObjectPath [0x0x7729d131+561]

Traceback (most recent call last):
  File "C:\Users\Trenkwalder\Documents\GitHub\beudei\whatsapp_gonder.py", line 34, in whatsapp_mesaj_gonder
    mesaj_kutusu = wait.until(
                   ^^^^^^^^^^^
  File "C:\Users\Trenkwalder\AppData\Local\Packages\PythonSoftwareFoundation.Python.3.11_qbz5n2kfra8p0\LocalCache\local-packages\Python311\site-packages\selenium\webdriver\support\wait.py", line 137, in until
    value = method(self._driver)
            ^^^^^^^^^^^^^^^^^^^^
  File "C:\Users\Trenkwalder\AppData\Local\Packages\PythonSoftwareFoundation.Python.3.11_qbz5n2kfra8p0\LocalCache\local-packages\Python311\site-packages\selenium\webdriver\support\expected_conditions.py", line 110, in _predicate
    return driver.find_element(*locator)
           ^^^^^^^^^^^^^^^^^^^^^^^^^^^^^
  File "C:\Users\Trenkwalder\AppData\Local\Packages\PythonSoftwareFoundation.Python.3.11_qbz5n2kfra8p0\LocalCache\local-packages\Python311\site-packages\selenium\webdriver\remote\webdriver.py", line 917, in find_element
    return self.execute(Command.FIND_ELEMENT, {"using": by, "value": value})["value"]
           ^^^^^^^^^^^^^^^^^^^^^^^^^^^^^^^^^^^^^^^^^^^^^^^^^^^^^^^^^^^^^^^^^
  File "C:\Users\Trenkwalder\AppData\Local\Packages\PythonSoftwareFoundation.Python.3.11_qbz5n2kfra8p0\LocalCache\local-packages\Python311\site-packages\selenium\webdriver\remote\webdriver.py", line 448, in execute
    self.error_handler.check_response(response)
  File "C:\Users\Trenkwalder\AppData\Local\Packages\PythonSoftwareFoundation.Python.3.11_qbz5n2kfra8p0\LocalCache\local-packages\Python311\site-packages\selenium\webdriver\remote\errorhandler.py", line 232, in check_response
    raise exception_class(message, screen, stacktrace)
selenium.common.exceptions.InvalidSessionIdException: Message: invalid session id: session deleted as the browser has closed the connection
from disconnected: not connected to DevTools
  (Session info: chrome=138.0.7204.158)
Stacktrace:
	GetHandleVerifier [0x0x9f1a33+62339]
	GetHandleVerifier [0x0x9f1a74+62404]
	(No symbol) [0x0x832123]
	(No symbol) [0x0x821b30]
	(No symbol) [0x0x83f8f2]
	(No symbol) [0x0x8a5cbc]
	(No symbol) [0x0x8c0089]
	(No symbol) [0x0x89f1b6]
	(No symbol) [0x0x86e7a2]
	(No symbol) [0x0x86f644]
	GetHandleVerifier [0x0xc665c3+2637587]
	GetHandleVerifier [0x0xc619ca+2618138]
	GetHandleVerifier [0x0xa184aa+220666]
	GetHandleVerifier [0x0xa088d8+156200]
	GetHandleVerifier [0x0xa0f06d+182717]
	GetHandleVerifier [0x0x9f9978+94920]
	GetHandleVerifier [0x0x9f9b02+95314]
	GetHandleVerifier [0x0x9e4c4a+9626]
	BaseThreadInitThunk [0x0x75f45d49+25]
	RtlInitializeExceptionChain [0x0x7729d1ab+107]
	RtlGetAppContainerNamedObjectPath [0x0x7729d131+561]


During handling of the above exception, another exception occurred:

Traceback (most recent call last):
  File "C:\Users\Trenkwalder\Documents\GitHub\beudei\whatsapp_gonder.py", line 45, in whatsapp_mesaj_gonder
    driver.save_screenshot("whatsapp_error.png")
  File "C:\Users\Trenkwalder\AppData\Local\Packages\PythonSoftwareFoundation.Python.3.11_qbz5n2kfra8p0\LocalCache\local-packages\Python311\site-packages\selenium\webdriver\remote\webdriver.py", line 1013, in save_screenshot
    return self.get_screenshot_as_file(filename)
           ^^^^^^^^^^^^^^^^^^^^^^^^^^^^^^^^^^^^^
  File "C:\Users\Trenkwalder\AppData\Local\Packages\PythonSoftwareFoundation.Python.3.11_qbz5n2kfra8p0\LocalCache\local-packages\Python311\site-packages\selenium\webdriver\remote\webdriver.py", line 988, in get_screenshot_as_file
    png = self.get_screenshot_as_png()
          ^^^^^^^^^^^^^^^^^^^^^^^^^^^^
  File "C:\Users\Trenkwalder\AppData\Local\Packages\PythonSoftwareFoundation.Python.3.11_qbz5n2kfra8p0\LocalCache\local-packages\Python311\site-packages\selenium\webdriver\remote\webdriver.py", line 1022, in get_screenshot_as_png
    return b64decode(self.get_screenshot_as_base64().encode("ascii"))
                     ^^^^^^^^^^^^^^^^^^^^^^^^^^^^^^^
  File "C:\Users\Trenkwalder\AppData\Local\Packages\PythonSoftwareFoundation.Python.3.11_qbz5n2kfra8p0\LocalCache\local-packages\Python311\site-packages\selenium\webdriver\remote\webdriver.py", line 1032, in get_screenshot_as_base64
    return self.execute(Command.SCREENSHOT)["value"]
           ^^^^^^^^^^^^^^^^^^^^^^^^^^^^^^^^
  File "C:\Users\Trenkwalder\AppData\Local\Packages\PythonSoftwareFoundation.Python.3.11_qbz5n2kfra8p0\LocalCache\local-packages\Python311\site-packages\selenium\webdriver\remote\webdriver.py", line 448, in execute
    self.error_handler.check_response(response)
  File "C:\Users\Trenkwalder\AppData\Local\Packages\PythonSoftwareFoundation.Python.3.11_qbz5n2kfra8p0\LocalCache\local-packages\Python311\site-packages\selenium\webdriver\remote\errorhandler.py", line 232, in check_response
    raise exception_class(message, screen, stacktrace)
selenium.common.exceptions.InvalidSessionIdException: Message: invalid session id
Stacktrace:
	GetHandleVerifier [0x0x9f1a33+62339]
	GetHandleVerifier [0x0x9f1a74+62404]
	(No symbol) [0x0x831f80]
	(No symbol) [0x0x86da98]
	(No symbol) [0x0x89f276]
	(No symbol) [0x0x89ae75]
	(No symbol) [0x0x89a3f6]
	(No symbol) [0x0x803a45]
	(No symbol) [0x0x803f9e]
	(No symbol) [0x0x80442d]
	GetHandleVerifier [0x0xc665c3+2637587]
	GetHandleVerifier [0x0xc619ca+2618138]
	GetHandleVerifier [0x0xa184aa+220666]
	GetHandleVerifier [0x0xa088d8+156200]
	GetHandleVerifier [0x0xa0f06d+182717]
	(No symbol) [0x0x803710]
	(No symbol) [0x0x802f1d]
	GetHandleVerifier [0x0xd9a65c+3899308]
	BaseThreadInitThunk [0x0x75f45d49+25]
	RtlInitializeExceptionChain [0x0x7729d1ab+107]
	RtlGetAppContainerNamedObjectPath [0x0x7729d131+561]

Traceback (most recent call last):
  File "C:\Users\Trenkwalder\AppData\Local\Packages\PythonSoftwareFoundation.Python.3.11_qbz5n2kfra8p0\LocalCache\local-packages\Python311\site-packages\urllib3\connectionpool.py", line 787, in urlopen
    response = self._make_request(
               ^^^^^^^^^^^^^^^^^^^
  File "C:\Users\Trenkwalder\AppData\Local\Packages\PythonSoftwareFoundation.Python.3.11_qbz5n2kfra8p0\LocalCache\local-packages\Python311\site-packages\urllib3\connectionpool.py", line 534, in _make_request
    response = conn.getresponse()
               ^^^^^^^^^^^^^^^^^^
  File "C:\Users\Trenkwalder\AppData\Local\Packages\PythonSoftwareFoundation.Python.3.11_qbz5n2kfra8p0\LocalCache\local-packages\Python311\site-packages\urllib3\connection.py", line 516, in getresponse
    httplib_response = super().getresponse()
                       ^^^^^^^^^^^^^^^^^^^^^
  File "C:\Program Files\WindowsApps\PythonSoftwareFoundation.Python.3.11_3.11.2544.0_x64__qbz5n2kfra8p0\Lib\http\client.py", line 1395, in getresponse
    response.begin()
  File "C:\Program Files\WindowsApps\PythonSoftwareFoundation.Python.3.11_3.11.2544.0_x64__qbz5n2kfra8p0\Lib\http\client.py", line 325, in begin
    version, status, reason = self._read_status()
                              ^^^^^^^^^^^^^^^^^^^
  File "C:\Program Files\WindowsApps\PythonSoftwareFoundation.Python.3.11_3.11.2544.0_x64__qbz5n2kfra8p0\Lib\http\client.py", line 286, in _read_status
    line = str(self.fp.readline(_MAXLINE + 1), "iso-8859-1")
               ^^^^^^^^^^^^^^^^^^^^^^^^^^^^^^
  File "C:\Program Files\WindowsApps\PythonSoftwareFoundation.Python.3.11_3.11.2544.0_x64__qbz5n2kfra8p0\Lib\socket.py", line 706, in readinto
    return self._sock.recv_into(b)
           ^^^^^^^^^^^^^^^^^^^^^^^
ConnectionResetError: [WinError 10054] Varolan bir bağlantı uzaktaki bir ana bilgisayar tarafından zorla kapatıldı

During handling of the above exception, another exception occurred:

Traceback (most recent call last):
  File "C:\Users\Trenkwalder\Documents\GitHub\beudei\whatsapp_gonder.py", line 34, in whatsapp_mesaj_gonder
    mesaj_kutusu = wait.until(
                   ^^^^^^^^^^^
  File "C:\Users\Trenkwalder\AppData\Local\Packages\PythonSoftwareFoundation.Python.3.11_qbz5n2kfra8p0\LocalCache\local-packages\Python311\site-packages\selenium\webdriver\support\wait.py", line 137, in until
    value = method(self._driver)
            ^^^^^^^^^^^^^^^^^^^^
  File "C:\Users\Trenkwalder\AppData\Local\Packages\PythonSoftwareFoundation.Python.3.11_qbz5n2kfra8p0\LocalCache\local-packages\Python311\site-packages\selenium\webdriver\support\expected_conditions.py", line 110, in _predicate
    return driver.find_element(*locator)
           ^^^^^^^^^^^^^^^^^^^^^^^^^^^^^
  File "C:\Users\Trenkwalder\AppData\Local\Packages\PythonSoftwareFoundation.Python.3.11_qbz5n2kfra8p0\LocalCache\local-packages\Python311\site-packages\selenium\webdriver\remote\webdriver.py", line 917, in find_element
    return self.execute(Command.FIND_ELEMENT, {"using": by, "value": value})["value"]
           ^^^^^^^^^^^^^^^^^^^^^^^^^^^^^^^^^^^^^^^^^^^^^^^^^^^^^^^^^^^^^^^^^
  File "C:\Users\Trenkwalder\AppData\Local\Packages\PythonSoftwareFoundation.Python.3.11_qbz5n2kfra8p0\LocalCache\local-packages\Python311\site-packages\selenium\webdriver\remote\webdriver.py", line 446, in execute
    response = self.command_executor.execute(driver_command, params)
               ^^^^^^^^^^^^^^^^^^^^^^^^^^^^^^^^^^^^^^^^^^^^^^^^^^^^^
  File "C:\Users\Trenkwalder\AppData\Local\Packages\PythonSoftwareFoundation.Python.3.11_qbz5n2kfra8p0\LocalCache\local-packages\Python311\site-packages\selenium\webdriver\remote\remote_connection.py", line 404, in execute
    return self._request(command_info[0], url, body=data)
           ^^^^^^^^^^^^^^^^^^^^^^^^^^^^^^^^^^^^^^^^^^^^^^
  File "C:\Users\Trenkwalder\AppData\Local\Packages\PythonSoftwareFoundation.Python.3.11_qbz5n2kfra8p0\LocalCache\local-packages\Python311\site-packages\selenium\webdriver\remote\remote_connection.py", line 428, in _request
    response = self._conn.request(method, url, body=body, headers=headers, timeout=self._client_config.timeout)
               ^^^^^^^^^^^^^^^^^^^^^^^^^^^^^^^^^^^^^^^^^^^^^^^^^^^^^^^^^^^^^^^^^^^^^^^^^^^^^^^^^^^^^^^^^^^^^^^^
  File "C:\Users\Trenkwalder\AppData\Local\Packages\PythonSoftwareFoundation.Python.3.11_qbz5n2kfra8p0\LocalCache\local-packages\Python311\site-packages\urllib3\_request_methods.py", line 143, in request
    return self.request_encode_body(
           ^^^^^^^^^^^^^^^^^^^^^^^^^
  File "C:\Users\Trenkwalder\AppData\Local\Packages\PythonSoftwareFoundation.Python.3.11_qbz5n2kfra8p0\LocalCache\local-packages\Python311\site-packages\urllib3\_request_methods.py", line 278, in request_encode_body
    return self.urlopen(method, url, **extra_kw)
           ^^^^^^^^^^^^^^^^^^^^^^^^^^^^^^^^^^^^^
  File "C:\Users\Trenkwalder\AppData\Local\Packages\PythonSoftwareFoundation.Python.3.11_qbz5n2kfra8p0\LocalCache\local-packages\Python311\site-packages\urllib3\poolmanager.py", line 443, in urlopen
    response = conn.urlopen(method, u.request_uri, **kw)
               ^^^^^^^^^^^^^^^^^^^^^^^^^^^^^^^^^^^^^^^^^
  File "C:\Users\Trenkwalder\AppData\Local\Packages\PythonSoftwareFoundation.Python.3.11_qbz5n2kfra8p0\LocalCache\local-packages\Python311\site-packages\urllib3\connectionpool.py", line 841, in urlopen
    retries = retries.increment(
              ^^^^^^^^^^^^^^^^^^
  File "C:\Users\Trenkwalder\AppData\Local\Packages\PythonSoftwareFoundation.Python.3.11_qbz5n2kfra8p0\LocalCache\local-packages\Python311\site-packages\urllib3\util\retry.py", line 474, in increment
    raise reraise(type(error), error, _stacktrace)
          ^^^^^^^^^^^^^^^^^^^^^^^^^^^^^^^^^^^^^^^^
  File "C:\Users\Trenkwalder\AppData\Local\Packages\PythonSoftwareFoundation.Python.3.11_qbz5n2kfra8p0\LocalCache\local-packages\Python311\site-packages\urllib3\util\util.py", line 38, in reraise
    raise value.with_traceback(tb)
  File "C:\Users\Trenkwalder\AppData\Local\Packages\PythonSoftwareFoundation.Python.3.11_qbz5n2kfra8p0\LocalCache\local-packages\Python311\site-packages\urllib3\connectionpool.py", line 787, in urlopen
    response = self._make_request(
               ^^^^^^^^^^^^^^^^^^^
  File "C:\Users\Trenkwalder\AppData\Local\Packages\PythonSoftwareFoundation.Python.3.11_qbz5n2kfra8p0\LocalCache\local-packages\Python311\site-packages\urllib3\connectionpool.py", line 534, in _make_request
    response = conn.getresponse()
               ^^^^^^^^^^^^^^^^^^
  File "C:\Users\Trenkwalder\AppData\Local\Packages\PythonSoftwareFoundation.Python.3.11_qbz5n2kfra8p0\LocalCache\local-packages\Python311\site-packages\urllib3\connection.py", line 516, in getresponse
    httplib_response = super().getresponse()
                       ^^^^^^^^^^^^^^^^^^^^^
  File "C:\Program Files\WindowsApps\PythonSoftwareFoundation.Python.3.11_3.11.2544.0_x64__qbz5n2kfra8p0\Lib\http\client.py", line 1395, in getresponse
    response.begin()
  File "C:\Program Files\WindowsApps\PythonSoftwareFoundation.Python.3.11_3.11.2544.0_x64__qbz5n2kfra8p0\Lib\http\client.py", line 325, in begin
    version, status, reason = self._read_status()
                              ^^^^^^^^^^^^^^^^^^^
  File "C:\Program Files\WindowsApps\PythonSoftwareFoundation.Python.3.11_3.11.2544.0_x64__qbz5n2kfra8p0\Lib\http\client.py", line 286, in _read_status
    line = str(self.fp.readline(_MAXLINE + 1), "iso-8859-1")
               ^^^^^^^^^^^^^^^^^^^^^^^^^^^^^^
  File "C:\Program Files\WindowsApps\PythonSoftwareFoundation.Python.3.11_3.11.2544.0_x64__qbz5n2kfra8p0\Lib\socket.py", line 706, in readinto
    return self._sock.recv_into(b)
           ^^^^^^^^^^^^^^^^^^^^^^^
urllib3.exceptions.ProtocolError: ('Connection aborted.', ConnectionResetError(10054, 'Varolan bir bağlantı uzaktaki bir ana bilgisayar tarafından zorla kapatıldı', None, 10054, None))

During handling of the above exception, another exception occurred:

Traceback (most recent call last):
  File "C:\Users\Trenkwalder\AppData\Local\Packages\PythonSoftwareFoundation.Python.3.11_qbz5n2kfra8p0\LocalCache\local-packages\Python311\site-packages\urllib3\connection.py", line 198, in _new_conn
    sock = connection.create_connection(
           ^^^^^^^^^^^^^^^^^^^^^^^^^^^^^
  File "C:\Users\Trenkwalder\AppData\Local\Packages\PythonSoftwareFoundation.Python.3.11_qbz5n2kfra8p0\LocalCache\local-packages\Python311\site-packages\urllib3\util\connection.py", line 85, in create_connection
    raise err
  File "C:\Users\Trenkwalder\AppData\Local\Packages\PythonSoftwareFoundation.Python.3.11_qbz5n2kfra8p0\LocalCache\local-packages\Python311\site-packages\urllib3\util\connection.py", line 73, in create_connection
    sock.connect(sa)
ConnectionRefusedError: [WinError 10061] Hedef makine etkin olarak reddettiğinden bağlantı kurulamadı

The above exception was the direct cause of the following exception:

Traceback (most recent call last):
  File "C:\Users\Trenkwalder\AppData\Local\Packages\PythonSoftwareFoundation.Python.3.11_qbz5n2kfra8p0\LocalCache\local-packages\Python311\site-packages\urllib3\connectionpool.py", line 787, in urlopen
    response = self._make_request(
               ^^^^^^^^^^^^^^^^^^^
  File "C:\Users\Trenkwalder\AppData\Local\Packages\PythonSoftwareFoundation.Python.3.11_qbz5n2kfra8p0\LocalCache\local-packages\Python311\site-packages\urllib3\connectionpool.py", line 493, in _make_request
    conn.request(
  File "C:\Users\Trenkwalder\AppData\Local\Packages\PythonSoftwareFoundation.Python.3.11_qbz5n2kfra8p0\LocalCache\local-packages\Python311\site-packages\urllib3\connection.py", line 445, in request
    self.endheaders()
  File "C:\Program Files\WindowsApps\PythonSoftwareFoundation.Python.3.11_3.11.2544.0_x64__qbz5n2kfra8p0\Lib\http\client.py", line 1298, in endheaders
    self._send_output(message_body, encode_chunked=encode_chunked)
  File "C:\Program Files\WindowsApps\PythonSoftwareFoundation.Python.3.11_3.11.2544.0_x64__qbz5n2kfra8p0\Lib\http\client.py", line 1058, in _send_output
    self.send(msg)
  File "C:\Program Files\WindowsApps\PythonSoftwareFoundation.Python.3.11_3.11.2544.0_x64__qbz5n2kfra8p0\Lib\http\client.py", line 996, in send
    self.connect()
  File "C:\Users\Trenkwalder\AppData\Local\Packages\PythonSoftwareFoundation.Python.3.11_qbz5n2kfra8p0\LocalCache\local-packages\Python311\site-packages\urllib3\connection.py", line 276, in connect
    self.sock = self._new_conn()
                ^^^^^^^^^^^^^^^^
  File "C:\Users\Trenkwalder\AppData\Local\Packages\PythonSoftwareFoundation.Python.3.11_qbz5n2kfra8p0\LocalCache\local-packages\Python311\site-packages\urllib3\connection.py", line 213, in _new_conn
    raise NewConnectionError(
urllib3.exceptions.NewConnectionError: <urllib3.connection.HTTPConnection object at 0x0000022EB8E56910>: Failed to establish a new connection: [WinError 10061] Hedef makine etkin olarak reddettiğinden bağlantı kurulamadı

The above exception was the direct cause of the following exception:

Traceback (most recent call last):
  File "C:\Users\Trenkwalder\Documents\GitHub\beudei\whatsapp_gonder.py", line 45, in whatsapp_mesaj_gonder
    driver.save_screenshot("whatsapp_error.png")
  File "C:\Users\Trenkwalder\AppData\Local\Packages\PythonSoftwareFoundation.Python.3.11_qbz5n2kfra8p0\LocalCache\local-packages\Python311\site-packages\selenium\webdriver\remote\webdriver.py", line 1013, in save_screenshot
    return self.get_screenshot_as_file(filename)
           ^^^^^^^^^^^^^^^^^^^^^^^^^^^^^^^^^^^^^
  File "C:\Users\Trenkwalder\AppData\Local\Packages\PythonSoftwareFoundation.Python.3.11_qbz5n2kfra8p0\LocalCache\local-packages\Python311\site-packages\selenium\webdriver\remote\webdriver.py", line 988, in get_screenshot_as_file
    png = self.get_screenshot_as_png()
          ^^^^^^^^^^^^^^^^^^^^^^^^^^^^
  File "C:\Users\Trenkwalder\AppData\Local\Packages\PythonSoftwareFoundation.Python.3.11_qbz5n2kfra8p0\LocalCache\local-packages\Python311\site-packages\selenium\webdriver\remote\webdriver.py", line 1022, in get_screenshot_as_png
    return b64decode(self.get_screenshot_as_base64().encode("ascii"))
                     ^^^^^^^^^^^^^^^^^^^^^^^^^^^^^^^
  File "C:\Users\Trenkwalder\AppData\Local\Packages\PythonSoftwareFoundation.Python.3.11_qbz5n2kfra8p0\LocalCache\local-packages\Python311\site-packages\selenium\webdriver\remote\webdriver.py", line 1032, in get_screenshot_as_base64
    return self.execute(Command.SCREENSHOT)["value"]
           ^^^^^^^^^^^^^^^^^^^^^^^^^^^^^^^^
  File "C:\Users\Trenkwalder\AppData\Local\Packages\PythonSoftwareFoundation.Python.3.11_qbz5n2kfra8p0\LocalCache\local-packages\Python311\site-packages\selenium\webdriver\remote\webdriver.py", line 446, in execute
    response = self.command_executor.execute(driver_command, params)
               ^^^^^^^^^^^^^^^^^^^^^^^^^^^^^^^^^^^^^^^^^^^^^^^^^^^^^
  File "C:\Users\Trenkwalder\AppData\Local\Packages\PythonSoftwareFoundation.Python.3.11_qbz5n2kfra8p0\LocalCache\local-packages\Python311\site-packages\selenium\webdriver\remote\remote_connection.py", line 404, in execute
    return self._request(command_info[0], url, body=data)
           ^^^^^^^^^^^^^^^^^^^^^^^^^^^^^^^^^^^^^^^^^^^^^^
  File "C:\Users\Trenkwalder\AppData\Local\Packages\PythonSoftwareFoundation.Python.3.11_qbz5n2kfra8p0\LocalCache\local-packages\Python311\site-packages\selenium\webdriver\remote\remote_connection.py", line 428, in _request
    response = self._conn.request(method, url, body=body, headers=headers, timeout=self._client_config.timeout)
               ^^^^^^^^^^^^^^^^^^^^^^^^^^^^^^^^^^^^^^^^^^^^^^^^^^^^^^^^^^^^^^^^^^^^^^^^^^^^^^^^^^^^^^^^^^^^^^^^
  File "C:\Users\Trenkwalder\AppData\Local\Packages\PythonSoftwareFoundation.Python.3.11_qbz5n2kfra8p0\LocalCache\local-packages\Python311\site-packages\urllib3\_request_methods.py", line 135, in request
    return self.request_encode_url(
           ^^^^^^^^^^^^^^^^^^^^^^^^
  File "C:\Users\Trenkwalder\AppData\Local\Packages\PythonSoftwareFoundation.Python.3.11_qbz5n2kfra8p0\LocalCache\local-packages\Python311\site-packages\urllib3\_request_methods.py", line 182, in request_encode_url
    return self.urlopen(method, url, **extra_kw)
           ^^^^^^^^^^^^^^^^^^^^^^^^^^^^^^^^^^^^^
  File "C:\Users\Trenkwalder\AppData\Local\Packages\PythonSoftwareFoundation.Python.3.11_qbz5n2kfra8p0\LocalCache\local-packages\Python311\site-packages\urllib3\poolmanager.py", line 443, in urlopen
    response = conn.urlopen(method, u.request_uri, **kw)
               ^^^^^^^^^^^^^^^^^^^^^^^^^^^^^^^^^^^^^^^^^
  File "C:\Users\Trenkwalder\AppData\Local\Packages\PythonSoftwareFoundation.Python.3.11_qbz5n2kfra8p0\LocalCache\local-packages\Python311\site-packages\urllib3\connectionpool.py", line 871, in urlopen
    return self.urlopen(
           ^^^^^^^^^^^^^
  File "C:\Users\Trenkwalder\AppData\Local\Packages\PythonSoftwareFoundation.Python.3.11_qbz5n2kfra8p0\LocalCache\local-packages\Python311\site-packages\urllib3\connectionpool.py", line 871, in urlopen
    return self.urlopen(
           ^^^^^^^^^^^^^
  File "C:\Users\Trenkwalder\AppData\Local\Packages\PythonSoftwareFoundation.Python.3.11_qbz5n2kfra8p0\LocalCache\local-packages\Python311\site-packages\urllib3\connectionpool.py", line 871, in urlopen
    return self.urlopen(
           ^^^^^^^^^^^^^
  File "C:\Users\Trenkwalder\AppData\Local\Packages\PythonSoftwareFoundation.Python.3.11_qbz5n2kfra8p0\LocalCache\local-packages\Python311\site-packages\urllib3\connectionpool.py", line 841, in urlopen
    retries = retries.increment(
              ^^^^^^^^^^^^^^^^^^
  File "C:\Users\Trenkwalder\AppData\Local\Packages\PythonSoftwareFoundation.Python.3.11_qbz5n2kfra8p0\LocalCache\local-packages\Python311\site-packages\urllib3\util\retry.py", line 519, in increment
    raise MaxRetryError(_pool, url, reason) from reason  # type: ignore[arg-type]
    ^^^^^^^^^^^^^^^^^^^^^^^^^^^^^^^^^^^^^^^^^^^^^^^^^^^
urllib3.exceptions.MaxRetryError: HTTPConnectionPool(host='localhost', port=62196): Max retries exceeded with url: /session/287d1896e8040e7e10d381eb8070da32/screenshot (Caused by NewConnectionError('<urllib3.connection.HTTPConnection object at 0x0000022EB8E56910>: Failed to establish a new connection: [WinError 10061] Hedef makine etkin olarak reddettiğinden bağlantı kurulamadı'))
